2024-08-21 12:11:22,837 ERROR [/Users/iguchiyasunari/Projects/Udemy/DjangoCourse/class_based_view/class_based_view/middleware.py:14] この名前は使用できないお
Traceback (most recent call last):
  File "/Users/iguchiyasunari/Projects/Udemy/DjangoCourse/myenv/lib/python3.12/site-packages/django/core/handlers/base.py", line 197, in _get_response
    response = wrapped_callback(request, *callback_args, **callback_kwargs)
               ^^^^^^^^^^^^^^^^^^^^^^^^^^^^^^^^^^^^^^^^^^^^^^^^^^^^^^^^^^^^
  File "/Users/iguchiyasunari/Projects/Udemy/DjangoCourse/myenv/lib/python3.12/site-packages/django/views/generic/base.py", line 104, in view
    return self.dispatch(request, *args, **kwargs)
           ^^^^^^^^^^^^^^^^^^^^^^^^^^^^^^^^^^^^^^^
  File "/Users/iguchiyasunari/Projects/Udemy/DjangoCourse/myenv/lib/python3.12/site-packages/django/views/generic/base.py", line 143, in dispatch
    return handler(request, *args, **kwargs)
           ^^^^^^^^^^^^^^^^^^^^^^^^^^^^^^^^^
  File "/Users/iguchiyasunari/Projects/Udemy/DjangoCourse/myenv/lib/python3.12/site-packages/django/views/generic/base.py", line 226, in get
    context = self.get_context_data(**kwargs)
              ^^^^^^^^^^^^^^^^^^^^^^^^^^^^^^^
  File "/Users/iguchiyasunari/Projects/Udemy/DjangoCourse/class_based_view/store/views.py", line 43, in get_context_data
    raise Http404("この名前は使用できないお")
django.http.response.Http404: この名前は使用できないお
